2025-02-19 13:53:58,005 - f2-trace - ERROR - Traceback (most recent call last):
  File "C:\Users\kitter\Downloads\New folder\f2\f2\crawlers\base_crawler.py", line 375, in post_fetch_data
    response.raise_for_status()
    ~~~~~~~~~~~~~~~~~~~~~~~~~^^
  File "C:\Users\kitter\AppData\Roaming\Python\Python313\site-packages\httpx\_models.py", line 829, in raise_for_status
    raise HTTPStatusError(message, request=request, response=self)
httpx.HTTPStatusError: Client error '404 Not Found' for url 'https://api.day.app/'
For more information check: https://developer.mozilla.org/en-US/docs/Web/HTTP/Status/404

During handling of the above exception, another exception occurred:

Traceback (most recent call last):
  File "C:\Users\kitter\Downloads\New folder\f2\f2\apps\bark\handler.py", line 48, in _send_bark_notification
    response = await crawler.post_bark_notification(params)
               ^^^^^^^^^^^^^^^^^^^^^^^^^^^^^^^^^^^^^^^^^^^^
  File "C:\Users\kitter\Downloads\New folder\f2\f2\apps\bark\crawler.py", line 42, in post_bark_notification
    return await self._fetch_post_json(
           ^^^^^^^^^^^^^^^^^^^^^^^^^^^^
        self.server_endpoint, params.model_dump(by_alias=True)
        ^^^^^^^^^^^^^^^^^^^^^^^^^^^^^^^^^^^^^^^^^^^^^^^^^^^^^^
    )
    ^
  File "C:\Users\kitter\Downloads\New folder\f2\f2\crawlers\base_crawler.py", line 206, in _fetch_post_json
    response = await self.post_fetch_data(endpoint, params)
               ^^^^^^^^^^^^^^^^^^^^^^^^^^^^^^^^^^^^^^^^^^^^
  File "C:\Users\kitter\Downloads\New folder\f2\f2\crawlers\base_crawler.py", line 386, in post_fetch_data
    self.handle_http_status_error(http_error, url, attempt + 1)
    ~~~~~~~~~~~~~~~~~~~~~~~~~~~~~^^^^^^^^^^^^^^^^^^^^^^^^^^^^^^
  File "C:\Users\kitter\Downloads\New folder\f2\f2\crawlers\base_crawler.py", line 459, in handle_http_status_error
    raise exception_class(_("HTTP状态码错误：{0}").format(status_code))
f2.exceptions.api_exceptions.APINotFoundError: HTTP状态码错误：404

